2023-04-13 04:38:57,424 --> ERROR - Error HTTP: https://crawler-test.com/status_codes/status_100 code:
Traceback (most recent call last):
  File "/home/ynr/PycharmProjects/crawler-project/.venv/lib/python3.11/site-packages/anyio/streams/tls.py", line 130, in _call_sslobject_method
    result = func(*args)
             ^^^^^^^^^^^
  File "/home/linuxbrew/.linuxbrew/opt/python@3.11/lib/python3.11/ssl.py", line 921, in read
    v = self._sslobj.read(len)
        ^^^^^^^^^^^^^^^^^^^^^^
ssl.SSLWantReadError: The operation did not complete (read) (_ssl.c:2546)

During handling of the above exception, another exception occurred:

Traceback (most recent call last):
  File "/home/ynr/PycharmProjects/crawler-project/.venv/lib/python3.11/site-packages/httpcore/backends/asyncio.py", line 34, in read
    return await self._stream.receive(max_bytes=max_bytes)
           ^^^^^^^^^^^^^^^^^^^^^^^^^^^^^^^^^^^^^^^^^^^^^^^
  File "/home/ynr/PycharmProjects/crawler-project/.venv/lib/python3.11/site-packages/anyio/streams/tls.py", line 195, in receive
    data = await self._call_sslobject_method(self._ssl_object.read, max_bytes)
           ^^^^^^^^^^^^^^^^^^^^^^^^^^^^^^^^^^^^^^^^^^^^^^^^^^^^^^^^^^^^^^^^^^^
  File "/home/ynr/PycharmProjects/crawler-project/.venv/lib/python3.11/site-packages/anyio/streams/tls.py", line 137, in _call_sslobject_method
    data = await self.transport_stream.receive()
           ^^^^^^^^^^^^^^^^^^^^^^^^^^^^^^^^^^^^^
  File "/home/ynr/PycharmProjects/crawler-project/.venv/lib/python3.11/site-packages/anyio/_backends/_asyncio.py", line 1265, in receive
    await self._protocol.read_event.wait()
  File "/home/linuxbrew/.linuxbrew/opt/python@3.11/lib/python3.11/asyncio/locks.py", line 213, in wait
    await fut
asyncio.exceptions.CancelledError

During handling of the above exception, another exception occurred:

Traceback (most recent call last):
  File "/home/ynr/PycharmProjects/crawler-project/.venv/lib/python3.11/site-packages/httpcore/_exceptions.py", line 10, in map_exceptions
    yield
  File "/home/ynr/PycharmProjects/crawler-project/.venv/lib/python3.11/site-packages/httpcore/backends/asyncio.py", line 32, in read
    with anyio.fail_after(timeout):
  File "/home/ynr/PycharmProjects/crawler-project/.venv/lib/python3.11/site-packages/anyio/_core/_tasks.py", line 118, in __exit__
    raise TimeoutError
TimeoutError

During handling of the above exception, another exception occurred:

Traceback (most recent call last):
  File "/home/ynr/PycharmProjects/crawler-project/.venv/lib/python3.11/site-packages/httpx/_transports/default.py", line 60, in map_httpcore_exceptions
    yield
  File "/home/ynr/PycharmProjects/crawler-project/.venv/lib/python3.11/site-packages/httpx/_transports/default.py", line 353, in handle_async_request
    resp = await self._pool.handle_async_request(req)
           ^^^^^^^^^^^^^^^^^^^^^^^^^^^^^^^^^^^^^^^^^^
  File "/home/ynr/PycharmProjects/crawler-project/.venv/lib/python3.11/site-packages/httpcore/_async/connection_pool.py", line 253, in handle_async_request
    raise exc
  File "/home/ynr/PycharmProjects/crawler-project/.venv/lib/python3.11/site-packages/httpcore/_async/connection_pool.py", line 237, in handle_async_request
    response = await connection.handle_async_request(request)
               ^^^^^^^^^^^^^^^^^^^^^^^^^^^^^^^^^^^^^^^^^^^^^^
  File "/home/ynr/PycharmProjects/crawler-project/.venv/lib/python3.11/site-packages/httpcore/_async/connection.py", line 90, in handle_async_request
    return await self._connection.handle_async_request(request)
           ^^^^^^^^^^^^^^^^^^^^^^^^^^^^^^^^^^^^^^^^^^^^^^^^^^^^
  File "/home/ynr/PycharmProjects/crawler-project/.venv/lib/python3.11/site-packages/httpcore/_async/http11.py", line 116, in handle_async_request
    raise exc
  File "/home/ynr/PycharmProjects/crawler-project/.venv/lib/python3.11/site-packages/httpcore/_async/http11.py", line 95, in handle_async_request
    ) = await self._receive_response_headers(**kwargs)
        ^^^^^^^^^^^^^^^^^^^^^^^^^^^^^^^^^^^^^^^^^^^^^^
  File "/home/ynr/PycharmProjects/crawler-project/.venv/lib/python3.11/site-packages/httpcore/_async/http11.py", line 159, in _receive_response_headers
    event = await self._receive_event(timeout=timeout)
            ^^^^^^^^^^^^^^^^^^^^^^^^^^^^^^^^^^^^^^^^^^
  File "/home/ynr/PycharmProjects/crawler-project/.venv/lib/python3.11/site-packages/httpcore/_async/http11.py", line 195, in _receive_event
    data = await self._network_stream.read(
           ^^^^^^^^^^^^^^^^^^^^^^^^^^^^^^^^
  File "/home/ynr/PycharmProjects/crawler-project/.venv/lib/python3.11/site-packages/httpcore/backends/asyncio.py", line 31, in read
    with map_exceptions(exc_map):
  File "/home/linuxbrew/.linuxbrew/opt/python@3.11/lib/python3.11/contextlib.py", line 155, in __exit__
    self.gen.throw(typ, value, traceback)
  File "/home/ynr/PycharmProjects/crawler-project/.venv/lib/python3.11/site-packages/httpcore/_exceptions.py", line 14, in map_exceptions
    raise to_exc(exc)
httpcore.ReadTimeout

The above exception was the direct cause of the following exception:

Traceback (most recent call last):
  File "/home/ynr/PycharmProjects/crawler-project/crawler/crawler_api.py", line 30, in _request
    response = await client.get(url)
               ^^^^^^^^^^^^^^^^^^^^^
  File "/home/ynr/PycharmProjects/crawler-project/.venv/lib/python3.11/site-packages/httpx/_client.py", line 1754, in get
    return await self.request(
           ^^^^^^^^^^^^^^^^^^^
  File "/home/ynr/PycharmProjects/crawler-project/.venv/lib/python3.11/site-packages/httpx/_client.py", line 1530, in request
    return await self.send(request, auth=auth, follow_redirects=follow_redirects)
           ^^^^^^^^^^^^^^^^^^^^^^^^^^^^^^^^^^^^^^^^^^^^^^^^^^^^^^^^^^^^^^^^^^^^^^
  File "/home/ynr/PycharmProjects/crawler-project/.venv/lib/python3.11/site-packages/httpx/_client.py", line 1617, in send
    response = await self._send_handling_auth(
               ^^^^^^^^^^^^^^^^^^^^^^^^^^^^^^^
  File "/home/ynr/PycharmProjects/crawler-project/.venv/lib/python3.11/site-packages/httpx/_client.py", line 1645, in _send_handling_auth
    response = await self._send_handling_redirects(
               ^^^^^^^^^^^^^^^^^^^^^^^^^^^^^^^^^^^^
  File "/home/ynr/PycharmProjects/crawler-project/.venv/lib/python3.11/site-packages/httpx/_client.py", line 1682, in _send_handling_redirects
    response = await self._send_single_request(request)
               ^^^^^^^^^^^^^^^^^^^^^^^^^^^^^^^^^^^^^^^^
  File "/home/ynr/PycharmProjects/crawler-project/.venv/lib/python3.11/site-packages/httpx/_client.py", line 1719, in _send_single_request
    response = await transport.handle_async_request(request)
               ^^^^^^^^^^^^^^^^^^^^^^^^^^^^^^^^^^^^^^^^^^^^^
  File "/home/ynr/PycharmProjects/crawler-project/.venv/lib/python3.11/site-packages/httpx/_transports/default.py", line 352, in handle_async_request
    with map_httpcore_exceptions():
  File "/home/linuxbrew/.linuxbrew/opt/python@3.11/lib/python3.11/contextlib.py", line 155, in __exit__
    self.gen.throw(typ, value, traceback)
  File "/home/ynr/PycharmProjects/crawler-project/.venv/lib/python3.11/site-packages/httpx/_transports/default.py", line 77, in map_httpcore_exceptions
    raise mapped_exc(message) from exc
httpx.ReadTimeout
2023-04-13 04:38:57,473 --> ERROR - --------------------------------------
2023-04-13 04:38:57,474 --> ERROR - Error on parsing soup  url 
Traceback (most recent call last):
  File "/home/ynr/PycharmProjects/crawler-project/crawler/crawler_api.py", line 107, in crawl
    links =await self.find_links(html)
           ^^^^^^^^^^^^^^^^^^^^^^^^^^^
  File "/home/ynr/PycharmProjects/crawler-project/crawler/crawler_api.py", line 63, in find_links
    soup =BeautifulSoup(html, "html.parser")
          ^^^^^^^^^^^^^^^^^^^^^^^^^^^^^^^^^^
  File "/home/ynr/PycharmProjects/crawler-project/.venv/lib/python3.11/site-packages/bs4/__init__.py", line 315, in __init__
    elif len(markup) <= 256 and (
         ^^^^^^^^^^^
TypeError: object of type 'bool' has no len()
2023-04-13 04:38:58,821 --> ERROR - Error HTTP: https://crawler-test.com/status_codes/status_101 code:
Traceback (most recent call last):
  File "/home/ynr/PycharmProjects/crawler-project/.venv/lib/python3.11/site-packages/anyio/streams/tls.py", line 130, in _call_sslobject_method
    result = func(*args)
             ^^^^^^^^^^^
  File "/home/linuxbrew/.linuxbrew/opt/python@3.11/lib/python3.11/ssl.py", line 921, in read
    v = self._sslobj.read(len)
        ^^^^^^^^^^^^^^^^^^^^^^
ssl.SSLWantReadError: The operation did not complete (read) (_ssl.c:2546)

During handling of the above exception, another exception occurred:

Traceback (most recent call last):
  File "/home/ynr/PycharmProjects/crawler-project/.venv/lib/python3.11/site-packages/httpcore/backends/asyncio.py", line 34, in read
    return await self._stream.receive(max_bytes=max_bytes)
           ^^^^^^^^^^^^^^^^^^^^^^^^^^^^^^^^^^^^^^^^^^^^^^^
  File "/home/ynr/PycharmProjects/crawler-project/.venv/lib/python3.11/site-packages/anyio/streams/tls.py", line 195, in receive
    data = await self._call_sslobject_method(self._ssl_object.read, max_bytes)
           ^^^^^^^^^^^^^^^^^^^^^^^^^^^^^^^^^^^^^^^^^^^^^^^^^^^^^^^^^^^^^^^^^^^
  File "/home/ynr/PycharmProjects/crawler-project/.venv/lib/python3.11/site-packages/anyio/streams/tls.py", line 137, in _call_sslobject_method
    data = await self.transport_stream.receive()
           ^^^^^^^^^^^^^^^^^^^^^^^^^^^^^^^^^^^^^
  File "/home/ynr/PycharmProjects/crawler-project/.venv/lib/python3.11/site-packages/anyio/_backends/_asyncio.py", line 1265, in receive
    await self._protocol.read_event.wait()
  File "/home/linuxbrew/.linuxbrew/opt/python@3.11/lib/python3.11/asyncio/locks.py", line 213, in wait
    await fut
asyncio.exceptions.CancelledError

During handling of the above exception, another exception occurred:

Traceback (most recent call last):
  File "/home/ynr/PycharmProjects/crawler-project/.venv/lib/python3.11/site-packages/httpcore/_exceptions.py", line 10, in map_exceptions
    yield
  File "/home/ynr/PycharmProjects/crawler-project/.venv/lib/python3.11/site-packages/httpcore/backends/asyncio.py", line 32, in read
    with anyio.fail_after(timeout):
  File "/home/ynr/PycharmProjects/crawler-project/.venv/lib/python3.11/site-packages/anyio/_core/_tasks.py", line 118, in __exit__
    raise TimeoutError
TimeoutError

During handling of the above exception, another exception occurred:

Traceback (most recent call last):
  File "/home/ynr/PycharmProjects/crawler-project/.venv/lib/python3.11/site-packages/httpx/_transports/default.py", line 60, in map_httpcore_exceptions
    yield
  File "/home/ynr/PycharmProjects/crawler-project/.venv/lib/python3.11/site-packages/httpx/_transports/default.py", line 353, in handle_async_request
    resp = await self._pool.handle_async_request(req)
           ^^^^^^^^^^^^^^^^^^^^^^^^^^^^^^^^^^^^^^^^^^
  File "/home/ynr/PycharmProjects/crawler-project/.venv/lib/python3.11/site-packages/httpcore/_async/connection_pool.py", line 253, in handle_async_request
    raise exc
  File "/home/ynr/PycharmProjects/crawler-project/.venv/lib/python3.11/site-packages/httpcore/_async/connection_pool.py", line 237, in handle_async_request
    response = await connection.handle_async_request(request)
               ^^^^^^^^^^^^^^^^^^^^^^^^^^^^^^^^^^^^^^^^^^^^^^
  File "/home/ynr/PycharmProjects/crawler-project/.venv/lib/python3.11/site-packages/httpcore/_async/connection.py", line 90, in handle_async_request
    return await self._connection.handle_async_request(request)
           ^^^^^^^^^^^^^^^^^^^^^^^^^^^^^^^^^^^^^^^^^^^^^^^^^^^^
  File "/home/ynr/PycharmProjects/crawler-project/.venv/lib/python3.11/site-packages/httpcore/_async/http11.py", line 116, in handle_async_request
    raise exc
  File "/home/ynr/PycharmProjects/crawler-project/.venv/lib/python3.11/site-packages/httpcore/_async/http11.py", line 95, in handle_async_request
    ) = await self._receive_response_headers(**kwargs)
        ^^^^^^^^^^^^^^^^^^^^^^^^^^^^^^^^^^^^^^^^^^^^^^
  File "/home/ynr/PycharmProjects/crawler-project/.venv/lib/python3.11/site-packages/httpcore/_async/http11.py", line 159, in _receive_response_headers
    event = await self._receive_event(timeout=timeout)
            ^^^^^^^^^^^^^^^^^^^^^^^^^^^^^^^^^^^^^^^^^^
  File "/home/ynr/PycharmProjects/crawler-project/.venv/lib/python3.11/site-packages/httpcore/_async/http11.py", line 195, in _receive_event
    data = await self._network_stream.read(
           ^^^^^^^^^^^^^^^^^^^^^^^^^^^^^^^^
  File "/home/ynr/PycharmProjects/crawler-project/.venv/lib/python3.11/site-packages/httpcore/backends/asyncio.py", line 31, in read
    with map_exceptions(exc_map):
  File "/home/linuxbrew/.linuxbrew/opt/python@3.11/lib/python3.11/contextlib.py", line 155, in __exit__
    self.gen.throw(typ, value, traceback)
  File "/home/ynr/PycharmProjects/crawler-project/.venv/lib/python3.11/site-packages/httpcore/_exceptions.py", line 14, in map_exceptions
    raise to_exc(exc)
httpcore.ReadTimeout

The above exception was the direct cause of the following exception:

Traceback (most recent call last):
  File "/home/ynr/PycharmProjects/crawler-project/crawler/crawler_api.py", line 30, in _request
    response = await client.get(url)
               ^^^^^^^^^^^^^^^^^^^^^
  File "/home/ynr/PycharmProjects/crawler-project/.venv/lib/python3.11/site-packages/httpx/_client.py", line 1754, in get
    return await self.request(
           ^^^^^^^^^^^^^^^^^^^
  File "/home/ynr/PycharmProjects/crawler-project/.venv/lib/python3.11/site-packages/httpx/_client.py", line 1530, in request
    return await self.send(request, auth=auth, follow_redirects=follow_redirects)
           ^^^^^^^^^^^^^^^^^^^^^^^^^^^^^^^^^^^^^^^^^^^^^^^^^^^^^^^^^^^^^^^^^^^^^^
  File "/home/ynr/PycharmProjects/crawler-project/.venv/lib/python3.11/site-packages/httpx/_client.py", line 1617, in send
    response = await self._send_handling_auth(
               ^^^^^^^^^^^^^^^^^^^^^^^^^^^^^^^
  File "/home/ynr/PycharmProjects/crawler-project/.venv/lib/python3.11/site-packages/httpx/_client.py", line 1645, in _send_handling_auth
    response = await self._send_handling_redirects(
               ^^^^^^^^^^^^^^^^^^^^^^^^^^^^^^^^^^^^
  File "/home/ynr/PycharmProjects/crawler-project/.venv/lib/python3.11/site-packages/httpx/_client.py", line 1682, in _send_handling_redirects
    response = await self._send_single_request(request)
               ^^^^^^^^^^^^^^^^^^^^^^^^^^^^^^^^^^^^^^^^
  File "/home/ynr/PycharmProjects/crawler-project/.venv/lib/python3.11/site-packages/httpx/_client.py", line 1719, in _send_single_request
    response = await transport.handle_async_request(request)
               ^^^^^^^^^^^^^^^^^^^^^^^^^^^^^^^^^^^^^^^^^^^^^
  File "/home/ynr/PycharmProjects/crawler-project/.venv/lib/python3.11/site-packages/httpx/_transports/default.py", line 352, in handle_async_request
    with map_httpcore_exceptions():
  File "/home/linuxbrew/.linuxbrew/opt/python@3.11/lib/python3.11/contextlib.py", line 155, in __exit__
    self.gen.throw(typ, value, traceback)
  File "/home/ynr/PycharmProjects/crawler-project/.venv/lib/python3.11/site-packages/httpx/_transports/default.py", line 77, in map_httpcore_exceptions
    raise mapped_exc(message) from exc
httpx.ReadTimeout
2023-04-13 04:38:58,826 --> ERROR - Error HTTP: https://crawler-test.com/status_codes/status_102 code:
Traceback (most recent call last):
  File "/home/ynr/PycharmProjects/crawler-project/.venv/lib/python3.11/site-packages/anyio/streams/tls.py", line 130, in _call_sslobject_method
    result = func(*args)
             ^^^^^^^^^^^
  File "/home/linuxbrew/.linuxbrew/opt/python@3.11/lib/python3.11/ssl.py", line 921, in read
    v = self._sslobj.read(len)
        ^^^^^^^^^^^^^^^^^^^^^^
ssl.SSLWantReadError: The operation did not complete (read) (_ssl.c:2546)

During handling of the above exception, another exception occurred:

Traceback (most recent call last):
  File "/home/ynr/PycharmProjects/crawler-project/.venv/lib/python3.11/site-packages/httpcore/backends/asyncio.py", line 34, in read
    return await self._stream.receive(max_bytes=max_bytes)
           ^^^^^^^^^^^^^^^^^^^^^^^^^^^^^^^^^^^^^^^^^^^^^^^
  File "/home/ynr/PycharmProjects/crawler-project/.venv/lib/python3.11/site-packages/anyio/streams/tls.py", line 195, in receive
    data = await self._call_sslobject_method(self._ssl_object.read, max_bytes)
           ^^^^^^^^^^^^^^^^^^^^^^^^^^^^^^^^^^^^^^^^^^^^^^^^^^^^^^^^^^^^^^^^^^^
  File "/home/ynr/PycharmProjects/crawler-project/.venv/lib/python3.11/site-packages/anyio/streams/tls.py", line 137, in _call_sslobject_method
    data = await self.transport_stream.receive()
           ^^^^^^^^^^^^^^^^^^^^^^^^^^^^^^^^^^^^^
  File "/home/ynr/PycharmProjects/crawler-project/.venv/lib/python3.11/site-packages/anyio/_backends/_asyncio.py", line 1265, in receive
    await self._protocol.read_event.wait()
  File "/home/linuxbrew/.linuxbrew/opt/python@3.11/lib/python3.11/asyncio/locks.py", line 213, in wait
    await fut
asyncio.exceptions.CancelledError

During handling of the above exception, another exception occurred:

Traceback (most recent call last):
  File "/home/ynr/PycharmProjects/crawler-project/.venv/lib/python3.11/site-packages/httpcore/_exceptions.py", line 10, in map_exceptions
    yield
  File "/home/ynr/PycharmProjects/crawler-project/.venv/lib/python3.11/site-packages/httpcore/backends/asyncio.py", line 32, in read
    with anyio.fail_after(timeout):
  File "/home/ynr/PycharmProjects/crawler-project/.venv/lib/python3.11/site-packages/anyio/_core/_tasks.py", line 118, in __exit__
    raise TimeoutError
TimeoutError

During handling of the above exception, another exception occurred:

Traceback (most recent call last):
  File "/home/ynr/PycharmProjects/crawler-project/.venv/lib/python3.11/site-packages/httpx/_transports/default.py", line 60, in map_httpcore_exceptions
    yield
  File "/home/ynr/PycharmProjects/crawler-project/.venv/lib/python3.11/site-packages/httpx/_transports/default.py", line 353, in handle_async_request
    resp = await self._pool.handle_async_request(req)
           ^^^^^^^^^^^^^^^^^^^^^^^^^^^^^^^^^^^^^^^^^^
  File "/home/ynr/PycharmProjects/crawler-project/.venv/lib/python3.11/site-packages/httpcore/_async/connection_pool.py", line 253, in handle_async_request
    raise exc
  File "/home/ynr/PycharmProjects/crawler-project/.venv/lib/python3.11/site-packages/httpcore/_async/connection_pool.py", line 237, in handle_async_request
    response = await connection.handle_async_request(request)
               ^^^^^^^^^^^^^^^^^^^^^^^^^^^^^^^^^^^^^^^^^^^^^^
  File "/home/ynr/PycharmProjects/crawler-project/.venv/lib/python3.11/site-packages/httpcore/_async/connection.py", line 90, in handle_async_request
    return await self._connection.handle_async_request(request)
           ^^^^^^^^^^^^^^^^^^^^^^^^^^^^^^^^^^^^^^^^^^^^^^^^^^^^
  File "/home/ynr/PycharmProjects/crawler-project/.venv/lib/python3.11/site-packages/httpcore/_async/http11.py", line 116, in handle_async_request
    raise exc
  File "/home/ynr/PycharmProjects/crawler-project/.venv/lib/python3.11/site-packages/httpcore/_async/http11.py", line 95, in handle_async_request
    ) = await self._receive_response_headers(**kwargs)
        ^^^^^^^^^^^^^^^^^^^^^^^^^^^^^^^^^^^^^^^^^^^^^^
  File "/home/ynr/PycharmProjects/crawler-project/.venv/lib/python3.11/site-packages/httpcore/_async/http11.py", line 159, in _receive_response_headers
    event = await self._receive_event(timeout=timeout)
            ^^^^^^^^^^^^^^^^^^^^^^^^^^^^^^^^^^^^^^^^^^
  File "/home/ynr/PycharmProjects/crawler-project/.venv/lib/python3.11/site-packages/httpcore/_async/http11.py", line 195, in _receive_event
    data = await self._network_stream.read(
           ^^^^^^^^^^^^^^^^^^^^^^^^^^^^^^^^
  File "/home/ynr/PycharmProjects/crawler-project/.venv/lib/python3.11/site-packages/httpcore/backends/asyncio.py", line 31, in read
    with map_exceptions(exc_map):
  File "/home/linuxbrew/.linuxbrew/opt/python@3.11/lib/python3.11/contextlib.py", line 155, in __exit__
    self.gen.throw(typ, value, traceback)
  File "/home/ynr/PycharmProjects/crawler-project/.venv/lib/python3.11/site-packages/httpcore/_exceptions.py", line 14, in map_exceptions
    raise to_exc(exc)
httpcore.ReadTimeout

The above exception was the direct cause of the following exception:

Traceback (most recent call last):
  File "/home/ynr/PycharmProjects/crawler-project/crawler/crawler_api.py", line 30, in _request
    response = await client.get(url)
               ^^^^^^^^^^^^^^^^^^^^^
  File "/home/ynr/PycharmProjects/crawler-project/.venv/lib/python3.11/site-packages/httpx/_client.py", line 1754, in get
    return await self.request(
           ^^^^^^^^^^^^^^^^^^^
  File "/home/ynr/PycharmProjects/crawler-project/.venv/lib/python3.11/site-packages/httpx/_client.py", line 1530, in request
    return await self.send(request, auth=auth, follow_redirects=follow_redirects)
           ^^^^^^^^^^^^^^^^^^^^^^^^^^^^^^^^^^^^^^^^^^^^^^^^^^^^^^^^^^^^^^^^^^^^^^
  File "/home/ynr/PycharmProjects/crawler-project/.venv/lib/python3.11/site-packages/httpx/_client.py", line 1617, in send
    response = await self._send_handling_auth(
               ^^^^^^^^^^^^^^^^^^^^^^^^^^^^^^^
  File "/home/ynr/PycharmProjects/crawler-project/.venv/lib/python3.11/site-packages/httpx/_client.py", line 1645, in _send_handling_auth
    response = await self._send_handling_redirects(
               ^^^^^^^^^^^^^^^^^^^^^^^^^^^^^^^^^^^^
  File "/home/ynr/PycharmProjects/crawler-project/.venv/lib/python3.11/site-packages/httpx/_client.py", line 1682, in _send_handling_redirects
    response = await self._send_single_request(request)
               ^^^^^^^^^^^^^^^^^^^^^^^^^^^^^^^^^^^^^^^^
  File "/home/ynr/PycharmProjects/crawler-project/.venv/lib/python3.11/site-packages/httpx/_client.py", line 1719, in _send_single_request
    response = await transport.handle_async_request(request)
               ^^^^^^^^^^^^^^^^^^^^^^^^^^^^^^^^^^^^^^^^^^^^^
  File "/home/ynr/PycharmProjects/crawler-project/.venv/lib/python3.11/site-packages/httpx/_transports/default.py", line 352, in handle_async_request
    with map_httpcore_exceptions():
  File "/home/linuxbrew/.linuxbrew/opt/python@3.11/lib/python3.11/contextlib.py", line 155, in __exit__
    self.gen.throw(typ, value, traceback)
  File "/home/ynr/PycharmProjects/crawler-project/.venv/lib/python3.11/site-packages/httpx/_transports/default.py", line 77, in map_httpcore_exceptions
    raise mapped_exc(message) from exc
httpx.ReadTimeout
2023-04-13 04:38:58,946 --> ERROR - --------------------------------------
2023-04-13 04:38:58,946 --> ERROR - Error on parsing soup  url 
Traceback (most recent call last):
  File "/home/ynr/PycharmProjects/crawler-project/crawler/crawler_api.py", line 107, in crawl
    links =await self.find_links(html)
           ^^^^^^^^^^^^^^^^^^^^^^^^^^^
  File "/home/ynr/PycharmProjects/crawler-project/crawler/crawler_api.py", line 63, in find_links
    soup =BeautifulSoup(html, "html.parser")
          ^^^^^^^^^^^^^^^^^^^^^^^^^^^^^^^^^^
  File "/home/ynr/PycharmProjects/crawler-project/.venv/lib/python3.11/site-packages/bs4/__init__.py", line 315, in __init__
    elif len(markup) <= 256 and (
         ^^^^^^^^^^^
TypeError: object of type 'bool' has no len()
2023-04-13 04:38:59,070 --> ERROR - --------------------------------------
2023-04-13 04:38:59,071 --> ERROR - Error on parsing soup  url 
Traceback (most recent call last):
  File "/home/ynr/PycharmProjects/crawler-project/crawler/crawler_api.py", line 107, in crawl
    links =await self.find_links(html)
           ^^^^^^^^^^^^^^^^^^^^^^^^^^^
  File "/home/ynr/PycharmProjects/crawler-project/crawler/crawler_api.py", line 63, in find_links
    soup =BeautifulSoup(html, "html.parser")
          ^^^^^^^^^^^^^^^^^^^^^^^^^^^^^^^^^^
  File "/home/ynr/PycharmProjects/crawler-project/.venv/lib/python3.11/site-packages/bs4/__init__.py", line 315, in __init__
    elif len(markup) <= 256 and (
         ^^^^^^^^^^^
TypeError: object of type 'bool' has no len()
